Error loading DirectML model: [Errno 2] No such file or directory: './models/ppo_directml_20250326_202801/final_model'
Traceback (most recent call last):
  File "C:\Users\14gma\Documents\FANUC-ML-1\src\core\train_robot_rl_positioning_revamped.py", line 2965, in evaluate_model_wrapper
    if directml_model.load(model_path):
       ^^^^^^^^^^^^^^^^^^^^^^^^^^^^^^^
  File "C:\Users\14gma\Documents\FANUC-ML-1\src\core\train_robot_rl_positioning_revamped.py", line 2798, in load
    raise e
  File "C:\Users\14gma\Documents\FANUC-ML-1\src\core\train_robot_rl_positioning_revamped.py", line 2736, in load
    checkpoint = torch.load(path, map_location='cpu')
                 ^^^^^^^^^^^^^^^^^^^^^^^^^^^^^^^^^^^^
  File "C:\Users\14gma\AppData\Local\Packages\PythonSoftwareFoundation.Python.3.11_qbz5n2kfra8p0\LocalCache\local-packages\Python311\site-packages\torch\serialization.py", line 1065, in load
    with _open_file_like(f, 'rb') as opened_file:
         ^^^^^^^^^^^^^^^^^^^^^^^^
  File "C:\Users\14gma\AppData\Local\Packages\PythonSoftwareFoundation.Python.3.11_qbz5n2kfra8p0\LocalCache\local-packages\Python311\site-packages\torch\serialization.py", line 468, in _open_file_like
    return _open_file(name_or_buffer, mode)
           ^^^^^^^^^^^^^^^^^^^^^^^^^^^^^^^^
  File "C:\Users\14gma\AppData\Local\Packages\PythonSoftwareFoundation.Python.3.11_qbz5n2kfra8p0\LocalCache\local-packages\Python311\site-packages\torch\serialization.py", line 449, in __init__
    super().__init__(open(name, mode))
                     ^^^^^^^^^^^^^^^^
FileNotFoundError: [Errno 2] No such file or directory: './models/ppo_directml_20250326_202801/final_model'
